Workbook
Name سعر_التر_المربع_شهريا: ورقة1!$J$2+[1]ورقة1!$G$12:$I$12

Sheet ورقة1
A1: 1 | H1: المعيارا لدائم لحساب القسط الشهري بدلالة قيمة البنود التالية وفق السعر المتفق عليع بتاريخ توقيع العقد
A2: مساحة الشقة | B2: 98 | C2: الطابق الأول | D2: شقة رقم | E2: التحويل من لاحق الخصص | F2: عدد الأقساط | G2: قيمة القسط الشهري | H2: مسلسل | I2: نوع العمل | J2: الوحدة | K2: السعر الافرادي | L2: الكمية | M2: السعر الاجمالي | N2: السعر الافرادي | O2: الكمية | P2: السعر الاجمالي
E3: =[2]ورقة1!$H$49 | F3: 60 | G3: =G5/F3*1.05 | K3: بتاريخ توقيع العقد | N3: بتاريخ دفع القسط
E4: =N11*E3 | H4: 1 | I4: ثمن حديد مبروم واصل الى موقع العمل | J4: كغ | K4: 10200 | L4: 30 | M4: =(K4*L4) | N4: 8260 | O4: 30 | P4: =(N4*O4)
A5: سعر المتر المربع عند التوقيع | B5: =CEILING(M12*SUM(O47,1),100) | F5: سعر الأمتار الباقية | G5: =G6*B6 | H5: 2 | I5: ثمن اسمنت واصل الى موقع العمل | J5: كيس | K5: 38000 | L5: 4 | M5: =(K5*L5) | N5: 95000 | O5: 4 | P5: =(N5*O5)
A6: سعر المتر المربع شهريا | B6: =CEILING(N12*SUM(O47,1),100) | F6: الأمتار الباقية | G6: =B2-H50 | H6: 3 | I6: ثمن بلوك اسمنتي سامكة 15 سم واصل | J6: بلوكة | K6: 1950 | L6: 50 | M6: =(K6*L6) | N6: 3800 | O6: 50 | P6: =(N6*O6)
A7: قيمة الشقة عند توقيع العقد | B7: =CEILING(B2*B5,100) | H7: 4 | I7: اجور كوفارج و صب حديد وتحديد بيتون | J7: م3 | K7: 60000 | L7: 1 | M7: =(K7*L7) | N7: 190000 | O7: 1 | P7: =(N7*O7)
I8: مسلح لزوم قواعد و اعمدة و بلاطة هوردي
B9: سعر المتر الشهري | C9: قيمة القسط | D9: مجموع تراكمي | E9: تاريخ القسط | G9: عدد الامتار المباعة | H9: 5 | I9: ثمن مواد حصوية جرجرة \بحص + نحاته \ واصل الى الموقع | J9: م3 | K9: 120000 | L9: 2 | M9: =(K9*L9) | N9: 253000 | O9: 2 | P9: =(N9*O9)
A10: دفعة أولى | B10: 1096900 | C10: 19587354 | E10: 2023\7\20 | G10: =C10/B10 | H10: 6 | I10: اجور عمل لعامـل عادي 7 ساعات | J10: يوم | K10: 30000 | L10: 1 | M10: =(K10*L10) | N10: 60000 | O10: 1 | P10: =(N10*O10)
A11: القسط 2 | B11: 1141400 | C11: 11000000 | E11: 2023\7\29 | G11: =C11/B11 | H11: القيمة الاجمالية للبنود السابقة بتاريخ العقد | M11: =SUM(M4:M10) | N11: =SUM(P4:P10)
A12: القسط 3 | B12: 1677100 | C12: 5000000 | E12: 2023\9\3 | G12: =C12/B12 | H12: سعر المتر المربع من الشقة المباعة وفق العقد | M12: =(M11*1.125) | N12: =(N11*1.125)
A13: القسط 4 | B13: 1861700 | C13: 5000000 | E13: 2023\10\8 | G13: =C13/B13
A14: القسط 5 | B14: 1902600 | C14: 5000000 | E14: 2023\11\13 | G14: =C14/B14
A15: القسط 6 | B15: 1939700 | C15: 4000000 | E15: 3\12\2023 | G15: =C15/B15 | O15: 0
A16: القسط 7 | B16: 1958300 | C16: 5000000 | E16: 2024\1\9 | G16: =C16/B16 | I16: الطابق | J16: -3 | K16: -2 | L16: -1 | M16: 0 | N16: 1 | O16: 2 | P16: 3 | Q16: 4
A17: القسط 8 | B17: 1959100 | C17: 5000000 | E17: 2024\2\7 | G17: =C17/B17 | I17: الشقة | J17: 0 | K17: 0 | L17: 0 | M17: 0 | N17: 0 | O17: 0 | P17: 1 | Q17: 0
A18: القسط 9 | B18: 1952100 | C18: 5000000 | E18: 2024\3\3 | G18: =C18/B18 | I18: معامل الطابق | J18: =0.12*J17 | K18: =0.06*K17 | L18: =0.03*L17 | M18: =0.15*M17 | N18: =0.12*N17 | O18: =0.06*O17 | P18: =0.015*P17 | Q18: =0.007*Q17
A19: القسط 10 | B19: 1915000 | C19: 5000000 | E19: 2024\4\4 | G19: =C19/B19
A20: القسط 11 | B20: 1970700 | C20: 5000000 | E20: 2024\5\5 | G20: =C20/B20
A21: القسط 12 | B21: 2046300 | C21: 5000000 | E21: 2024\6\5 | G21: =C21/B21
A22: القسط 13 | B22: 2088400 | C22: 7200000 | E22: 2024\6\27 | G22: =C22/B22 | I22: قيمة المصعد | J22: 0
A23: القسط 14 | B23: 2021500 | C23: 7500000 | E23: 2024\8\8 | G23: =C23/B23 | I23: عدد الدرجات حسب الطابق | J23: 20 | K23: 40 | L23: 60 | M23: 80 | N23: 100 | O23: 120 | P23: 140 | Q23: 160
A24: القسط 15 | B24: 2013700 | C24: 6000000 | E24: 2024\9\8 | G24: =C24/B24 | I24: ما يلحق الدرجة الواحدة بدلالة المتر من قيمة المصعد | L24: =((J22/SUM(J23:Q23))/M12)/(ورقة2!J7*ورقة2!L6)
A25: القسط 16 | B25: 2038500 | C25: 5000000 | E25: 2024\11\17 | G25: =C25/B25 | I25: معامل المصعد | J25: =L24*1*J17*J23 | K25: =L24*2*K17*K23 | L25: =L24*3*L17*L23 | M25: =L24*4*M17*M23 | N25: =L24*5*N17*N23 | O25: =L24*6*O17*O23 | P25: =L24*7*P17*P23 | Q25: =L24*8*Q17*Q23 | R25: =SUM(J25:Q25)
A26: القسط 17 | B26: 2020200 | C26: 6780000 | E26: 2025\1\9 | G26: =C26/B26
A27: القسط 18 | B27: =1909400*0.9 | C27: 6050000 | D27: تخفيض 10% | E27: 2025\1\20 | G27: =C27/B27
B28: =B6*0.9 | D28: تخفيض 10%
A29: القسط 19 | B29: =B6*0.85 | C29: 0 | D29: تخفيض 15% | F29: 10 مليون | G29: =C29/B29 | I29: الوجيبة | J29: أماميه | K29: جانبيه | L29: جانبيه | M29: خلفية | N29: لاحق التخصص | O29: متخصص
A30: القسط 20 | B30: =B6*0.8 | C30: 0 | D30: تخفيض 20% | F30: 20 | G30: =C30/B30 | J30: 3 | K30: 0 | L30: 0 | M30: 0 | N30: 1 | O30: 1
A31: القسط 21 | B31: 1220000 | C31: 31000000 | D31: تخفيض 25% | E31: 2026\8\4 | F31: 30 | G31: =C31/B31 | I31: معامل الوجيبة | J31: =(J30*O32)/1000 | K31: =(K30*O33)/1000 | L31: =(L30)/1000 | M31: =(M30)*O33/1000 | N31: 0 | O31: 0
A32: القسط 22 | N32: شارع رئيسي | O32: 12
A33: القسط 23 | I33: معامل الشارع | J33: رئيسي | K33: تنظيمي | N33: شارع فرعي | O33: 1
A34: القسط 24 | I34: شارعين متوازين | K34: =J301 | M34: =J31+M31 | N34: شارع | O34: 0
A35: القسط 25 | I35: شارعين متقاطعين | J35: 0 | K35: 0 | M35: =(J31+L31*O33)*J35
A36: القسط 26
A37: القسط 27 | I37: الاتــــــــجـــاه | J37: جنوب | K37: شرق | L37: شمال | M37: غرب | N37: الاطلالة | O37: الموقع
A38: القسط 28 | J38: 0 | K38: 0 | L38: 0 | M38: 1 | N38: 1 | O38: 1
A39: القسط 29 | I39: معامل الاتجــــــــاه | J39: =J38*0.022 | K39: =K38*0.018 | L39: =L38*0.009 | M39: =M38*0.014 | N39: 0 | O39: 0
A40: القسط 30
...

Sheet ورقة2
A1: مساحة الشقة | B1: 100 | C1: نوع العمل | D1: الوحدة | E1: السعر الافرادي | F1: الكمية | G1: السعر الاجمالي | I1: فراغ الطابق | J1: 3.15 | K1: ابعاد النوافذ | L1: =J4-J3 | M1: سعر المتر البواري | N1: 300 | Q1: اجرة تركيب م.ط مداخن | R1: 500
A2: معامل المداخن | B2: 5 | E2: بتاريخ توقيع العقد | I2: سماكة البلاطة | J2: 0.25 | K2: عرض النافذة | L2: 1.6 | M2: اجرة تركيب المتر | N2: 500
C3: ثمن حديد مبروم واصل الى موقع العمل | D3: كغ | E3: 320 | F3: 17 | G3: =(E3*F3) | I3: ارتفاع المنامات | J3: 1.05 | K3: عرض النافذة الوسطى | L3: 1.8 | M3: رمل مداخن | N3: 0.007
C4: ثمن اسمنت واصل الى موقع العمل | D4: كيس | E4: 2310 | F4: 1.35 | G4: =(E4*F4) | I4: ارتفاع العتب الخارجية | J4: 2.3 | K4: عرض الباب | L4: 1 | M4: اسمنت مداخن | N4: 0.04 | Q4: اجرة تركيب م.ط نوازل | R4: 700
C5: ثمن بلوك اسمنتي سامكة 15 سم واصل | D5: بلوكة | E5: 115 | F5: 7 | G5: =(E5*F5) | I5: ارتفاع العتب الداخلي | J5: 2.2 | K5: عدد الشقق | L5: 3 | M5: سعر م3 قيراوني | N5: 11000 | Q5: اجرة م2 كلسة داخلية | R5: 300
C6: اجور كوفارج و صب حديد وتحديد بيتون | D6: م3 | E6: 6000 | F6: 0.25 | G6: =(E6*F6) | I6: عدد المداخن | J6: 4 | K6: عدد الطوابق | L6: 5 | M6: بودرا | N6: 5500 | Q6: اجرة تركيب م2بلوك | R6: 250
C7: مسلح لزوم قواعد و اعمدة و بلاطة هوردي | I7: مساحة الطابق | J7: 300 | K7: سعر 1 كيلو لاصق طوبى | L7: 1600 | Q7: اجرة تركيب م2 رخام | R7: 500
C8: ثمن مواد حصوية جرجرة \بحص + نحاته \ واصل الى الموقع | D8: م3 | E8: 6500 | F8: 0.25 | G8: =(E8*F8) | Q8: اجرة تركيب م2 حجر | R8: 700
C9: اجور صقل + اسمنت | E9: 275 | F9: 1 | G9: =(E9*F9) | I9: قيمة ريغار | J9: 1 | Q9: اجرة تركيب م2 سيراميك | R9: 500
C10: اجور سقاية + شريط تربيط + هوالك | E10: 300 | F10: 1 | G10: =(E10*F10) | I10: سعر بوري 8 ً طوبى | J10: 6400 | Q10: اجرة تركيب م.ط شعيرة | R10: 500
C11: أعمدة | D11: م3 | G11: 2700 | I11: سعر بوري 6 ً طوبى | J11: 4600 | Q11: اجرة تركيب م2 رخام
C12: اجور الرخصة | E12: 1300 | F12: 1 | G12: =(E12*F12) | H12: =SUM(G3:G11) | I12: سعر بوري 4 ً طوبى | J12: 2650 | Q12: اجرة تركيب م2 رخام
C13: المداخن | D13: م | E13: =N1+N2+( N3*(E8*1.5))+( N4*E4) | F13: =J6*(J1+J2)*B2+1.5 | G13: =(F13*E13)/B1 | I13: سعر بوري 3 ً طوبى | J13: 1500 | Q13: اجرة تركيب م2 رخام
C14: نوازل صحية | D14: م | E14: =((J12+J13)*7)+(J14+J15)*4+(L7/3)+(R4*8) | G14: =E14/B1 | H14: =SUM(G3:G14) | I14: سعر تي 4 ً | J14: 800 | Q14: أجرة م2 كلسة خارجية | R14: 700
C15: درج | E15: 0 | G15: 0 | I15: سعر تي 3 ً | J15: 700
C16: منامات السطح و بيت الدرج | E16: =(SQRT(B1)*4)*(10*E5+R6)+E4+E4+(0.25*N6 ) | G16: =E14/B1 | I16: كوع مدفع 4 ً | J16: 1000
C17: كلسة خارجية | E17: =(SQRT(B1)*3*3.5*R14)+(SQRT(B1)*3*3.5*0.015*9*E4)+(SQRT(B1)*3*3.5*0.015*9*N5) | G17: =E17/B1 | I17: كواني 3 ً
C18: بلوك خارجي | E18: =(SQRT(B1)*4*3.25*R6)+((SQRT(B1)*3*3.25)/0.08)*J20+((SQRT(B1)*3*3.25)/0.08)/(80)*E4+((SQRT(B1)*3*3.25)/0.08)/(80)*0.2*N6 | G18: =E18/B1
C19: صرف صحي | E19: 40000 | G19: =E19/B1 | I19: سعر بلوك 10 سم | J19: 95
C20: قواعد و أساسات مسلحة | E20: =((((B1/8)*4)/L6)+( 0.5))*(7*E4+1.3*E8+E6+E3*70) | G20: =E20/B1 | I20: سعر بلوك 12 سم | J20: 100 | M20: =((B1/8)*6)/L6
C21: بيتون مغموس ونظافة | G21: 250 | I21: رخام تركي 3 سم | J21: 14000
C22: حفريات | D22: م3 | E22: =400000/(L5*L6) | G22: =E22/B1 | I22: رخام تركي 1.5 سم | J22: 7000
C23: جدران استندادية | G23: 2000
G24: =SUM(G3:G23)
C25: معامل الارض | G25: =G24*1.48
C26: معامل تنفيذ | G26: =G25*1.09
C27: معامل راس مال | G27: =G26*1.06 | I27: الطابق | J27: قبو 2 | K27: قبو 1 | L27: ارضي | M27: 1 | N27: 2 | O27: 3 | P27: 4
I28: معامل المداخن | J28: 7 | K28: 6 | L28: 5 | M28: 4 | N28: 3 | O28: 2 | P28: 1

Sheet ورقة3
A1: بيتنا our home | G1: نسخة الفريق الاول | H1: قيمة المواد شهريا | J1: كمية /م2/ واحد
A2: وصل استلام قسط
A3: انشاء المستخدم: م.محمد كامل علي | E3: تاريخ الانشاء | G3: =ورقة1!E31 | H3: حديد | I3: =ورقة1!N4 | J3: 30 | K3: كغ
E4: تاريخ الاستحقاق | G4: =G5 | H4: اسمنت | I4: =ورقة1!N5 | J4: 4 | K4: كيس
A5: رقم القسط | B5: 19 | E5: تاريخ الدفع | G5: =G3 | H5: بلوك | I5: =ورقة1!N6 | J5: 50 | K5: بلوكة
A6: اسم الفريق الثاني | B6: خولة محمد | H6: كوفراج | I6: =ورقة1!N7 | J6: 1 | K6: م3
A7: رقم الفريق الثاني | B7: 279 | H7: رمل | I7: =ورقة1!N9 | J7: 2 | K7: م3
A8: مجموع المبلغ | B8: =ورقة1!H48 | C8: فقط مئة وتسعة واربعون مليون ومئة وسبعة عشر الف وثلاثمئة واربع وخمسون ليرة | H8: عامل | I8: =ورقة1!N10 | J8: 1 | K8: يوم
A9: سعر المتر بتاريخه | B9: =ورقة1!B6 | E9: الرسوم | H9: الامتار المحولة | I9: =ورقة1!G31
A10: تفاصيل القسط المدفوع | C10: اصل القسط | G10: سعر المتر بعد التخيض 25% | H10: اجمالي الامتار المحولة | I10: =ورقة1!H50
C11: 31000000 | E11: فقط واحد وثلاثون مليون ليرة سورية | G11: =ورقة1!B31
A13: المستلم : | B13: ملاحظة : تم استلام المبالغ على ثلاثة دفعات | G13: م.محمد كامل علي
B14: الدفعة الأولى :1500$*10300 الدفعة الثانية 1000$*10900
B15: والدفعة الثالثة :500$*12000 وهي تتمة حساب الشقة والباقي 1350000حولت الى اعمال البلوك
A25: بيتنا our home | G25: نسخة الفريق الثاني | H25: قيمة المواد شهريا | J25: كمية /م2/ واحد
A26: وصل استلام قسط
A27: انشاء المستخدم: م.محمد كامل علي | E27: تاريخ الانشاء | G27: =G3 | H27: حديد | I27: =I3 | J27: 30 | K27: كغ
E28: تاريخ الاستحقاق | G28: =G3 | H28: اسمنت | I28: =I4 | J28: 4 | K28: كيس
A29: رقم القسط | B29: =B5 | E29: تاريخ الدفع | G29: =G5 | H29: بلوك | I29: =I5 | J29: 50 | K29: بلوكة
A30: اسم الفريق الثاني | B30: =B6 | H30: كوفراج | I30: =I6 | J30: 1 | K30: م3
A31: رقم الفريق الثاني | B31: =B7 | H31: رمل | I31: =I7 | J31: 2 | K31: م3
A32: مجموع المبلغ | B32: =B8 | C32: =C8 | H32: عامل | I32: =I8 | J32: 1 | K32: يوم
A33: =A9 | B33: =B9 | E33: الرسوم | H33: الامتار المحولة | I33: =I9
A34: تفاصيل القسط المدفوع | C34: اصل القسط | G34: =G10 | H34: اجمالي الامتار المحولة | I34: =I10
C35: =C11 | E35: =E11 | G35: =G11
A37: المستلم : | B37: =B13 | G37: م.محمد كامل علي
B38: =B14
B39: =B15
