Workbook

Sheet ورقة1
A1: شقة لاحقة التخصص يوشع عباس | E1: الحريف | H1: المعيارا لدائم لحساب القسط الشهري بدلالة قيمة البنود التالية وفق السعر المتفق عليع بتاريخ توقيع العقد
A2: مساحة الشقة | B2: 100 | C2: الطابق الأول | D2: شقة رقم | E2: المحول الشهري بالمتار | F2: عدد الاقساط | G2: القسط الشهري | H2: مسلسل | I2: نوع العمل | J2: الوحدة | K2: السعر الافرادي | L2: الكمية | M2: السعر الاجمالي | N2: السعر الافرادي | O2: الكمية | P2: السعر الاجمالي
E3: =C10/B6 -> 0.1397624 | F3: 120 | K3: بتاريخ توقيع العقد | N3: بتاريخ دفع القسط
A4: معادل موقع الشقة | B4: 1 | H4: 1 | I4: ثمن حديد مبروم واصل الى موقع العمل | J4: كغ | K4: 1420 | L4: 30 | M4: =(K4*L4) -> 42600 | N4: 4225 | O4: 30 | P4: =(N4*O4) -> 126750
A5: سعر المتر المربع عند التوقيع | B5: =M12 -> 107600 | H5: 2 | I5: ثمن اسمنت واصل الى موقع العمل | J5: كيس | K5: 5000 | L5: 4 | M5: =(K5*L5) -> 20000 | N5: 11500 | O5: 4 | P5: =(N5*O5) -> 46000
A6: سعر المتر المربع شهريا | B6: =N12 -> 357750 | H6: 3 | I6: ثمن بلوك اسمنتي سامكة 15 سم واصل | J6: بلوكة | K6: 210 | L6: 50 | M6: =(K6*L6) -> 10500 | N6: 900 | O6: 50 | P6: =(N6*O6) -> 45000
A7: قيمة الشقة عند توقيع العقد | B7: =CEILING(B2*B5,100) -> 10760000 | H7: 4 | I7: اجور كوفارج و صب حديد وتحديد بيتون | J7: م3 | K7: 10000 | L7: 1 | M7: =(K7*L7) -> 10000 | N7: 27000 | O7: 1 | P7: =(N7*O7) -> 27000
I8: مسلح لزوم قواعد و اعمدة و بلاطة هوردي
B9: سعر المتر الشهري | C9: قيمة القسط | D9: معادل التخفيض | E9: تاريخ القسط | G9: عدد الامتار المباعة | H9: 5 | I9: ثمن مواد حصوية جرجرة \بحص + نحاته \ واصل الى الموقع | J9: م3 | K9: 9500 | L9: 2 | M9: =(K9*L9) -> 19000 | N9: 50000 | O9: 2 | P9: =(N9*O9) -> 100000
A10: دفعة أولى | B10: 107600 | C10: 50000 | D10: 1 | E10: 44075 | G10: =C10/B10 -> 0.46468401 | H10: 6 | I10: اجور عمل لعامـل عادي 7 ساعات | J10: يوم | K10: 5500 | L10: 1 | M10: =(K10*L10) -> 5500 | N10: 13000 | O10: 1 | P10: =(N10*O10) -> 13000
A11: القسط 1 | B11: 117800 | C11: 15000 | E11: 44110 | G11: =C11/B11 -> 0.12733447 | H11: القيمة الاجمالية للبنود السابقة بتاريخ العقد | M11: =SUM(M4:M10) -> 107600 | N11: =SUM(P4:P10) -> 357750
A12: القسط 2 | B12: 124200 | C12: 10000 | E12: 44144 | G12: =C12/B12 -> 0.080515298 | H12: سعر المتر المربع من الشقة المباعة وفق العقد | M12: =(M11*1) -> 107600 | N12: =(N11*1) -> 357750
A13: القسط 3 | B13: 132950 | C13: 50000 | E13: 14/12/2020 | G13: =C13/B13 -> 0.37608123
A14: القسط 4 | B14: 157150 | C14: 15000 | D14: 1 | E14: 44348 | G14: =C14/B14 -> 0.095450207
A15: القسط 5 | B15: 174450 | C15: 15000 | D15: 1 | E15: 44349 | G15: =C15/B15 -> 0.085984523
A16: القسط 6 | B16: 225600 | C16: 15000 | D16: 1 | E16: 44272 | G16: =C16/B16 -> 0.066489362 | I16: الطابق
A17: القسط 7 | B17: 224600 | C17: 25000 | D17: 1 | E17: 44381 | G17: =C17/B17 -> 0.11130899 | I17: الشقة
A18: القسط 8 | B18: 299600 | C18: 80000 | D18: 1 | E18: 41203 | G18: =C18/B18 -> 0.2670227 | I18: معامل الطابق
A19: القسط 9 | B19: 357750 | C19: 20000 | D19: 1 | E19: 44807 | G19: =C19/B19 -> 0.055904962
A20: القسط 10 | B20: 0 | D20: 1 | G20: 0
A21: القسط 11 | B21: 0 | D21: 1 | G21: 0
A22: القسط 12 | B22: 0 | D22: 1 | G22: 0 | I22: قيمة المصعد
A23: القسط 13 | B23: 0 | D23: 1 | G23: 0 | I23: عدد الدرجات حسب الطابق
A24: القسط 14 | B24: 0 | D24: 1 | G24: 0 | I24: مايلحق الدرجة الواحدة من قيمة المصعد
A25: القسط 15 | B25: 0 | D25: 1 | G25: 0 | I25: معامل المصعد
A26: القسط 16 | B26: 0 | D26: 1 | G26: 0
A27: القسط 17 | B27: 0 | D27: 1 | G27: 0
A28: القسط 18 | B28: 0 | D28: 1 | G28: 0 | I28: الوجيبة
A29: القسط 19 | B29: 0 | D29: 1 | G29: 0
A30: القسط 20 | B30: 0 | D30: 1 | G30: 0 | I30: معامل الوجيبة
A31: القسط 21 | B31: 0 | D31: 1 | G31: 0
A32: القسط 22 | B32: 0 | D32: 1 | G32: 0 | I32: معامل الشارع
A33: القسط 23 | B33: 0 | D33: 1 | G33: 0 | I33: شارعين متوازيين
A34: القسط 25 | B34: 0 | D34: 1 | G34: 0 | I34: شارعين متقاطعين
A35: القسط 26 | B35: 0 | D35: 1 | G35: 0
A36: القسط 27 | B36: 0 | D36: 1 | G36: 0 | I36: الاتجاه
A37: القسط 28 | B37: 0 | D37: 1 | G37: 0
A38: القسط 29 | B38: 0 | D38: 1 | G38: 0 | I38: معامل الاتجاه
A39: القسط 30 | B39: 0 | D39: 1 | G39: 0
A40: القسط 31 | B40: 0 | D40: 1 | G40: 0 | I40: الشقة
...

Sheet ورقة2
A1: مساحة الشقة | B1: 100 | C1: نوع العمل | D1: الوحدة | E1: السعر الافرادي | F1: الكمية | G1: السعر الاجمالي | I1: فراغ الطابق | J1: 3.15 | K1: ابعاد النوافذ | L1: =J4-J3 -> 1.25 | M1: سعر المتر البواري | N1: 300 | Q1: اجرة تركيب م.ط مداخن | R1: 500
A2: معامل المداخن | B2: 5 | E2: بتاريخ توقيع العقد | I2: سماكة البلاطة | J2: 0.25 | K2: عرض النافذة | L2: 1.6 | M2: اجرة تركيب المتر | N2: 500
C3: ثمن حديد مبروم واصل الى موقع العمل | D3: كغ | E3: 320 | F3: 17 | G3: =(E3*F3) -> 5440 | I3: ارتفاع المنامات | J3: 1.05 | K3: عرض النافذة الوسطى | L3: 1.8 | M3: رمل مداخن | N3: 0.007
C4: ثمن اسمنت واصل الى موقع العمل | D4: كيس | E4: 2310 | F4: 1.35 | G4: =(E4*F4) -> 3118.5 | I4: ارتفاع العتب الخارجية | J4: 2.3 | K4: عرض الباب | L4: 1 | M4: اسمنت مداخن | N4: 0.04 | Q4: اجرة تركيب م.ط نوازل | R4: 700
C5: ثمن بلوك اسمنتي سامكة 15 سم واصل | D5: بلوكة | E5: 115 | F5: 7 | G5: =(E5*F5) -> 805 | I5: ارتفاع العتب الداخلي | J5: 2.2 | K5: عدد الشقق | L5: 3 | M5: سعر م3 قيراوني | N5: 11000 | Q5: اجرة م2 كلسة داخلية | R5: 300
C6: اجور كوفارج و صب حديد وتحديد بيتون | D6: م3 | E6: 6000 | F6: 0.25 | G6: =(E6*F6) -> 1500 | I6: عدد المداخن | J6: 4 | K6: عدد الطوابق | L6: 5 | M6: بودرا | N6: 5500 | Q6: اجرة تركيب م2بلوك | R6: 250
C7: مسلح لزوم قواعد و اعمدة و بلاطة هوردي | I7: مساحة الطابق | J7: 300 | K7: سعر 1 كيلو لاصق طوبى | L7: 1600 | Q7: اجرة تركيب م2 رخام | R7: 500
C8: ثمن مواد حصوية جرجرة \بحص + نحاته \ واصل الى الموقع | D8: م3 | E8: 6500 | F8: 0.25 | G8: =(E8*F8) -> 1625 | Q8: اجرة تركيب م2 حجر | R8: 700
C9: اجور صقل + اسمنت | E9: 275 | F9: 1 | G9: =(E9*F9) -> 275 | I9: قيمة ريغار | J9: 1 | Q9: اجرة تركيب م2 سيراميك | R9: 500
C10: اجور سقاية + شريط تربيط + هوالك | E10: 300 | F10: 1 | G10: =(E10*F10) -> 300 | I10: سعر بوري 8 ً طوبى | J10: 6400 | Q10: اجرة تركيب م.ط شعيرة | R10: 500
C11: أعمدة | D11: م3 | G11: 2700 | I11: سعر بوري 6 ً طوبى | J11: 4600 | Q11: اجرة تركيب م2 رخام
C12: اجور الرخصة | E12: 1300 | F12: 1 | G12: =(E12*F12) -> 1300 | H12: =SUM(G3:G11) -> 15763.5 | I12: سعر بوري 4 ً طوبى | J12: 2650 | Q12: اجرة تركيب م2 رخام
C13: المداخن | D13: م | E13: =N1+N2+( N3*(E8*1.5))+( N4*E4) -> 960.65 | F13: =J6*(J1+J2)*B2+1.5 -> 69.5 | G13: =(F13*E13)/B1 -> 667.65175 | I13: سعر بوري 3 ً طوبى | J13: 1500 | Q13: اجرة تركيب م2 رخام
C14: نوازل صحية | D14: م | E14: =((J12+J13)*7)+(J14+J15)*4+(L7/3)+(R4*8) -> 41183.333 | G14: =E14/B1 -> 411.83333 | H14: =SUM(G3:G14) -> 18142.985 | I14: سعر تي 4 ً | J14: 800 | Q14: أجرة م2 كلسة خارجية | R14: 700
C15: درج | E15: 0 | G15: 0 | I15: سعر تي 3 ً | J15: 700
C16: منامات السطح و بيت الدرج | E16: =(SQRT(B1)*4)*(10*E5+R6)+E4+E4+(0.25*N6 ) -> 61995 | G16: =E14/B1 -> 411.83333 | I16: كوع مدفع 4 ً | J16: 1000
C17: كلسة خارجية | E17: =(SQRT(B1)*3*3.5*R14)+(SQRT(B1)*3*3.5*0.015*9*E4)+(SQRT(B1)*3*3.5*0.015*9*N5) -> 262169.25 | G17: =E17/B1 -> 2621.6925 | I17: كواني 3 ً
C18: بلوك خارجي | E18: =(SQRT(B1)*4*3.25*R6)+((SQRT(B1)*3*3.25)/0.08)*J20+((SQRT(B1)*3*3.25)/0.08)/(80)*E4+((SQRT(B1)*3*3.25)/0.08)/(80)*0.2*N6 -> 206324.22 | G18: =E18/B1 -> 2063.2422
C19: صرف صحي | E19: 40000 | G19: =E19/B1 -> 400 | I19: سعر بلوك 10 سم | J19: 95
C20: قواعد و أساسات مسلحة | E20: =((((B1/8)*4)/L6)+( 0.5))*(7*E4+1.3*E8+E6+E3*70) -> 556710 | G20: =E20/B1 -> 5567.1 | I20: سعر بلوك 12 سم | J20: 100 | M20: =((B1/8)*6)/L6 -> 15
C21: بيتون مغموس ونظافة | G21: 250 | I21: رخام تركي 3 سم | J21: 14000
C22: حفريات | D22: م3 | E22: =400000/(L5*L6) -> 26666.667 | G22: =E22/B1 -> 266.66667 | I22: رخام تركي 1.5 سم | J22: 7000
C23: جدران استندادية | G23: 2000
G24: =SUM(G3:G23) -> 31723.52
C25: معامل الارض | G25: =G24*1.3 -> 41240.576
C26: معامل تنفيذ | G26: =G25*1.06 -> 43715.01
C27: معامل راس مال | G27: =G26*1.06 -> 46337.911 | I27: الطابق | J27: قبو 2 | K27: قبو 1 | L27: ارضي | M27: 1 | N27: 2 | O27: 3 | P27: 4
I28: معامل المداخن | J28: 7 | K28: 6 | L28: 5 | M28: 4 | N28: 3 | O28: 2 | P28: 1

Sheet ورقة3
A1: بيتنا our home | H1: نسخة الفريق الاول
A2: وصل استلام قسط | I2: قيمة المواد شهريا
B3: انشاء المستخدم: م.محمد كامل علي | E3: تاريخ الانشاء | H3: =ورقة1!E17 -> 44381 | I3: حديد | J3: =ورقة1!N4 -> 4225
E4: تاريخ الاستحقاق | H4: =H3 -> 44381 | I4: اسمنت | J4: =ورقة1!N5 -> 11500
A5: رقم القسط | C5: 10 | E5: تاريخ الدفع | H5: =H4 -> 44381 | I5: بلوك | J5: =ورقة1!N6 -> 900
A6: اسم الفريق الثاني | C6: يوشع ثابت عباس | I6: كوفراج | J6: =ورقة1!N7 -> 27000
A7: رقم الفريق الثاني | C7: 220 | I7: رمل | J7: =ورقة1!N9 -> 50000
A8: مجموع المبلغ | C8: =ورقة1!H47 -> 295000 | E8: فقط مئة و خمس و تسعون الف ليرة سورية | I8: عامل | J8: =ورقة1!N10 -> 13000
E9: الرسوم | I9: الامتار المحولة | J9: =ورقة1!G17 -> 0.11130899
A10: تفاصيل القسط المدفوع | C10: اصل القسط | H10: اجمالي القسط المدفوع | I10: اجمالي الامتار المحولة | J10: =ورقة1!H49 -> 1.7307758
C11: 25000 | E11: 0 | H11: =C11+D11+E11 -> 25000
A12: رقم القسط المدفوع | B12: =C5 -> 10 | E12: فقط خمس و عشرون ألف ليرة سورية
A13: عدد الاقساط المتبقية | B13: =ورقة1!F3-C5 -> 110 | E13: توقيع الفريق الاول : | H13: م.محمد كامل علي
A25: بيتنا our home | H25: نسخة الفريق الثاني
A26: وصل استلام قسط | I26: قيمة المواد شهريا
B27: انشاء المستخدم: م.محمد كامل علي | E27: تاريخ الانشاء | H27: =H3 -> 44381 | I27: حديد | J27: =J3 -> 4225
E28: تاريخ الاستحقاق | H28: =H4 -> 44381 | I28: اسمنت | J28: =J4 -> 11500
A29: رقم القسط | C29: =C5 -> 10 | E29: تاريخ الدفع | H29: =H5 -> 44381 | I29: بلوك | J29: =J5 -> 900
A30: اسم الفريق الثاني | C30: =C6 -> يوشع ثابت عباس | I30: كوفراج | J30: =J6 -> 27000
A31: رقم الفريق الثاني | C31: =C7 -> 220 | I31: رمل | J31: =J7 -> 50000
A32: مجموع المبلغ | C32: =C8 -> 295000 | E32: =E8 -> فقط مئة و خمس و تسعون الف ليرة سورية | I32: عامل | J32: =J8 -> 13000
E33: الرسوم | I33: الامتار المحولة | J33: =J9 -> 0.11130899
A34: تفاصيل القسط المدفوع | C34: اصل القسط | H34: اجمالي المبلغ المدفوع | I34: اجمالي الامتار المحولة | J34: =J10 -> 1.7307758
C35: =C11 -> 25000 | E35: 0 | H35: =H11+D35+E34 -> 25000
A36: رقم القسط المدفوع | B36: =B12 -> 10 | E36: =E12 -> فقط خمس و عشرون ألف ليرة سورية
A37: عدد الاقساط المتبقية | B37: =B13 -> 110 | E37: توقيع الفريق الاول : | H37: م.محمد كامل علي
